<mujoco model="handwheel_valve">
  <option iterations="50" timestep="0.001" solver="PGS" gravity="0 0 -9.81" />

  <compiler angle="radian" meshdir="assets" eulerseq="zyx" autolimits="true" />

  <default>
    <joint limited="true" damping="0.01" armature="0.001" frictionloss="0.0" />
    <geom condim="4" contype="1" conaffinity="15" friction="0.9 0.2 0.2" solref="0.001 2" />
    <motor ctrllimited="true" />
    <equality solref="0.001 2" />
    <default class="visualgeom">
      <geom material="visualgeom" condim="1" contype="0" conaffinity="0" />
    </default>
  </default>

  <asset>
    <mesh name="base_link" file="base_link.stl" scale="0.001 0.001 0.001" />
    <mesh name="valve" file="valve.stl" scale="0.001 0.001 0.001" />
    <!-- <texture name="texplane" type="2d" builtin="checker" rgb1=".0 .0 .0" rgb2=".8 .8 .8" width="100" height="100" />
    <material name="matplane" reflectance="0." texture="texplane" texrepeat="1 1" texuniform="true" /> -->
    <material name="visualgeom" rgba="0.5 0.9 0.2 1" />
  </asset>

  <worldbody>
    <!-- <light directional="true" diffuse="0.4 0.4 0.4" specular="0.1 0.1 0.1" pos="0 0 5.0" dir="0 0 -1" castshadow="false" />
    <light directional="true" diffuse="0.6 0.6 0.6" specular="0.2 0.2 0.2" pos="0 0 4" dir="0 0 -1" /> -->
    <!-- <geom name="ground" type="plane" pos="0 0 0" size="100 100 0.001" quat="1 0 0 0" material="matplane" condim="3" conaffinity="15" /> -->
    <camera name="fixed" pos="0 -3.0 0.6795626954691983" xyaxes="1 0 0 0 0 1" />
    <camera name="track" mode="trackcom" pos="0 -3.0 0.6795626954691983" xyaxes="1 0 0 0 0 1" />
    <body name="root" pos="0 0 0" quat="1 0 0 0">
      <!-- <freejoint name="root" /> -->
      <site name="imu" size="0.01" pos="0 0 0" rgba="0 0 0 0"/>
      <geom type="mesh" rgba="0.7 0.7 0.7 1" mesh="base_link" contype="1" conaffinity="0" density="0" group="1" class="visualgeom" />
      <geom type="mesh" rgba="0.7 0.7 0.7 1" mesh="base_link" mass="250" solimp="0.9 0.99 0.001" solref="0.01 1"/>
      <body name="valve" pos="0.11685 -0.23495 0.136595">
        <inertial pos="0 0 0.0131149" quat="0.5 0.5 -0.5 0.5" mass="0.117699" diaginertia="4.6e-05 2.6e-05 2.6e-05" />
        <joint name="Revolute" pos="0 0 0" axis="0 0 1"
       range="0 4.71239"
       damping="0.01"
       armature="0.001"
       frictionloss="0.0"
       actuatorfrcrange="-100 100" />

        <!-- damping="1.0" armature="0.01" frictionloss="0.1" /> -->
        <geom pos="-0.11685 0.23495 -0.136595" quat="1 0 0 0" type="mesh" rgba="0.7 0.7 0.7 1" mesh="valve" contype="1" conaffinity="0" density="0" group="1" class="visualgeom" />
        <geom type="mesh" rgba="0.7 0.7 0.7 1" mesh="valve" pos="-0.11685 0.23495 -0.136595" quat="1 0 0 0"  solimp="0.9 0.99 0.001" solref="0.01 1"/>
      </body>
    </body>
  </worldbody>

  <!-- <actuator>
    <motor name="Revolute" joint="Revolute" ctrllimited="true" ctrlrange="-100 100" gear="1" />
  </actuator> -->

  <!-- <sensor>
    <actuatorpos name="Revolute_p" actuator="Revolute" />
    <actuatorvel name="Revolute_v" actuator="Revolute" />
    <actuatorfrc name="Revolute_f" actuator="Revolute" noise="0.001" />
    <framequat name="orientation" objtype="site" noise="0.001" objname="imu" />
    <gyro name="angular-velocity" site="imu" noise="0.005" cutoff="34.9" />
  </sensor> -->
</mujoco>